Traceback (most recent call last):
  File "/usr/local/lib/python3.7/dist-packages/torch/serialization.py", line 308, in _check_seekable
    f.seek(f.tell())
AttributeError: 'NoneType' object has no attribute 'seek'
During handling of the above exception, another exception occurred:
Traceback (most recent call last):
  File "train.py", line 543, in <module>
    train(hyp, opt, device, tb_writer)
  File "train.py", line 87, in train
    ckpt = torch.load(weights, map_location=device)  # load checkpoint
  File "/usr/local/lib/python3.7/dist-packages/torch/serialization.py", line 579, in load
    with _open_file_like(f, 'rb') as opened_file:
  File "/usr/local/lib/python3.7/dist-packages/torch/serialization.py", line 235, in _open_file_like
    return _open_buffer_reader(name_or_buffer)
  File "/usr/local/lib/python3.7/dist-packages/torch/serialization.py", line 220, in __init__
    _check_seekable(buffer)
  File "/usr/local/lib/python3.7/dist-packages/torch/serialization.py", line 311, in _check_seekable
    raise_err_msg(["seek", "tell"], e)
  File "/usr/local/lib/python3.7/dist-packages/torch/serialization.py", line 304, in raise_err_msg
    raise type(e)(msg)
AttributeError: 'NoneType' object has no attribute 'seek'. You can only torch.load from a file that is seekable. Please pre-load the data into a buffer like io.BytesIO and try to load from it instead.